Workbook

Sheet How to rate
A1: Card set ratings: Cinema collection (4 sets x 3 variants x 10 cards = 120 cards)
A3: What to fill | B3: On the Ratings sheet: column I 'Rating (1-5)' (yellow, dropdown) and column J 'Comment' (light yellow, optional). On the Set picks sheet: your pick per set and any swaps or redos.
A4: Scale | B4: 5 = indistinguishable from the real cards; 4 = minor difference; 3 = noticeable difference; 2 = clearly different in places; 1 = different style.
A5: Judge | B5: Rendering (shapes, shading, materials, outlines), colour (warmth, saturation, contrast), composition (angle, size in frame, background) and whether the object fits the set.
A6: Full size | B6: Thumbnails are 200x223 px. Click 'open' in column K to see the 430x480 card.
A7: Codes | B7: LC = Love in the City, PP = Picture-Perfect Suburbia, OG = Once Upon a Garden, LI = The Lost Island. The Summary sheet averages your ratings automatically.
A9: Example (format only; not a real rating)
A10: Code | B10: Name | C10: Rating (1-5) | D10: Comment (optional)
A11: LC-A01 | B11: Rose Bouquet | C11: 4 | D11: Bow a little too glossy; otherwise matches the real cards.

Sheet Ratings
A1: Code | B1: Set | C1: Variant | D1: Concept | E1: Card | F1: Name | G1: Category | H1: Image | I1: Rating (1-5) | J1: Comment (optional) | K1: Full size
A2: LC-A01 | B2: Love in the City | C2: A | D2: First Date: classic date props and the city spots where it happens | E2: A01 | F2: Rose Bouquet | G2: 1 | I2: 5 | K2: open
A3: LC-A02 | B3: Love in the City | C3: A | D3: First Date: classic date props and the city spots where it happens | E3: A02 | F3: Rotary Phone | G3: 3 | I3: 5 | K3: open
A4: LC-A03 | B4: Love in the City | C4: A | D4: First Date: classic date props and the city spots where it happens | E4: A03 | F4: City Taxi | G4: 4 | I4: 5 | K4: open
A5: LC-A04 | B5: Love in the City | C5: A | D5: First Date: classic date props and the city spots where it happens | E5: A04 | F5: Heart Cupcake | G5: 2 | I5: 3 | K5: open
A6: LC-A05 | B6: Love in the City | C6: A | D6: First Date: classic date props and the city spots where it happens | E6: A05 | F6: Heart Chocolates | G6: 1 | I6: 5 | K6: open
A7: LC-A06 | B7: Love in the City | C7: A | D7: First Date: classic date props and the city spots where it happens | E7: A06 | F7: Park Bench | G7: 4 | I7: 3 | J7: Overall good but it seems like it is floating in the air instead of terrain | K7: open
A8: LC-A07 | B8: Love in the City | C8: A | D8: First Date: classic date props and the city spots where it happens | E8: A07 | F8: Record Player | G8: 3 | I8: 4 | J8: Maybe less details on object would be nice, everything else is perfect (colors, idea, etc) | K8: open
A9: LC-A08 | B9: Love in the City | C9: A | D9: First Date: classic date props and the city spots where it happens | E9: A08 | F9: Love Letter | G9: 1 | I9: 5 | K9: open
A10: LC-A09 | B10: Love in the City | C10: A | D10: First Date: classic date props and the city spots where it happens | E10: A09 | F10: Perfume | G10: 2 | I10: 4 | K10: open
A11: LC-A10 | B11: Love in the City | C11: A | D11: First Date: classic date props and the city spots where it happens | E11: A10 | F11: Flower Kiosk | G11: 4 | I11: 5 | K11: open
A12: LC-B01 | B12: Love in the City | C12: B | D12: Meet-Cute: chance encounters around town | E12: B01 | F12: Red Umbrella | G12: 1 | I12: 5 | K12: open
A13: LC-B02 | B13: Love in the City | C13: B | D13: Meet-Cute: chance encounters around town | E13: B02 | F13: Typewriter | G13: 3 | I13: 4 | J13: Too many details | K13: open
A14: LC-B03 | B14: Love in the City | C14: B | D14: Meet-Cute: chance encounters around town | E14: B03 | F14: Vintage Scooter | G14: 4 | I14: 5 | K14: open
A15: LC-B04 | B15: Love in the City | C15: B | D15: Meet-Cute: chance encounters around town | E15: B04 | F15: Heart Balloon | G15: 1 | I15: 3 | K15: open
A16: LC-B05 | B16: Love in the City | C16: B | D16: Meet-Cute: chance encounters around town | E16: B05 | F16: Matching Mugs | G16: 2 | I16: 4 | J16: Steam is far from ref (should be more realistic) | K16: open
A17: LC-B06 | B17: Love in the City | C17: B | D17: Meet-Cute: chance encounters around town | E17: B06 | F17: Cafe Table | G17: 4 | I17: 4 | K17: open
A18: LC-B07 | B18: Love in the City | C18: B | D18: Meet-Cute: chance encounters around town | E18: B07 | F18: Engagement Ring | G18: 1 | I18: 5 | K18: open
A19: LC-B08 | B19: Love in the City | C19: B | D19: Meet-Cute: chance encounters around town | E19: B08 | F19: Tulip Bucket | G19: 3 | I19: 4 | K19: open
A20: LC-B09 | B20: Love in the City | C20: B | D20: Meet-Cute: chance encounters around town | E20: B09 | F20: Heart Glasses | G20: 2 | I20: 4 | J20: Color blending a bit | K20: open
A21: LC-B10 | B21: Love in the City | C21: B | D21: Meet-Cute: chance encounters around town | E21: B10 | F21: Love Locks | G21: 4 | I21: 5 | K21: open
A22: LC-C01 | B22: Love in the City | C22: C | D22: Happily Ever After: the wedding finale | E22: C01 | F22: Wedding Rings | G22: 1 | I22: 3 | J22: Idea is great but rings looks like plastic more than like a metal | K22: open
A23: LC-C02 | B23: Love in the City | C23: C | D23: Happily Ever After: the wedding finale | E23: C02 | F23: Wedding Cake | G23: 3 | I23: 4 | J23: Too many details, maybe roses should be more simplistic | K23: open
A24: LC-C03 | B24: Love in the City | C24: C | D24: Happily Ever After: the wedding finale | E24: C03 | F24: Wedding Car | G24: 4 | I24: 4 | K24: open
A25: LC-C04 | B25: Love in the City | C25: C | D25: Happily Ever After: the wedding finale | E25: C04 | F25: Red Heel | G25: 2 | I25: 5 | K25: open
A26: LC-C05 | B26: Love in the City | C26: C | D26: Happily Ever After: the wedding finale | E26: C05 | F26: Bridal Bouquet | G26: 1 | I26: 2 | J26: Too detailed, background like this is not in any ref | K26: open
A27: LC-C06 | B27: Love in the City | C27: C | D27: Happily Ever After: the wedding finale | E27: C06 | F27: Garden Gazebo | G27: 4 | I27: 3 | J27: Too detailed | K27: open
A28: LC-C07 | B28: Love in the City | C28: C | D28: Happily Ever After: the wedding finale | E28: C07 | F28: Tiara | G28: 1 | I28: 4 | K28: open
A29: LC-C08 | B29: Love in the City | C29: C | D29: Happily Ever After: the wedding finale | E29: C08 | F29: Gift Box | G29: 3 | I29: 4 | K29: open
A30: LC-C09 | B30: Love in the City | C30: C | D30: Happily Ever After: the wedding finale | E30: C09 | F30: Heart Candles | G30: 2 | I30: 4 | K30: open
A31: LC-C10 | B31: Love in the City | C31: C | D31: Happily Ever After: the wedding finale | E31: C10 | F31: Chapel Bell | G31: 4 | I31: 5 | K31: open
A32: PP-A01 | B32: Picture-Perfect Suburbia | C32: A | D32: Home Sweet Home: the dream house and its gadgets | E32: A01 | F32: Pop-up Toaster | G32: 1 | I32: 4 | K32: open
A33: PP-A02 | B33: Picture-Perfect Suburbia | C33: A | D33: Home Sweet Home: the dream house and its gadgets | E33: A02 | F33: Retro TV | G33: 3 | I33: 5 | K33: open
A34: PP-A03 | B34: Picture-Perfect Suburbia | C34: A | D34: Home Sweet Home: the dream house and its gadgets | E34: A03 | F34: Dream House | G34: 4 | I34: 5 | K34: open
A35: PP-A04 | B35: Picture-Perfect Suburbia | C35: A | D35: Home Sweet Home: the dream house and its gadgets | E35: A04 | F35: Jelly Mould | G35: 2 | I35: 5 | K35: open
A36: PP-A05 | B36: Picture-Perfect Suburbia | C36: A | D36: Home Sweet Home: the dream house and its gadgets | E36: A05 | F36: Milk Bottle | G36: 1 | I36: 3 | K36: open
A37: PP-A06 | B37: Picture-Perfect Suburbia | C37: A | D37: Home Sweet Home: the dream house and its gadgets | E37: A06 | F37: Mailbox | G37: 4 | I37: 5 | K37: open
A38: PP-A07 | B38: Picture-Perfect Suburbia | C38: A | D38: Home Sweet Home: the dream house and its gadgets | E38: A07 | F38: Stand Mixer | G38: 3 | I38: 4 | K38: open
A39: PP-A08 | B39: Picture-Perfect Suburbia | C39: A | D39: Home Sweet Home: the dream house and its gadgets | E39: A08 | F39: Hula Hoop | G39: 1 | I39: 2 | K39: open
... A41: PP-A10 | B41: Picture-Perfect Suburbia | C41: A | D41: Home Sweet Home: the dream house and its gadgets | E41: A10 | F41: Station Wagon | G41: 4 | I41: 5 | K41: open
...

Sheet Set picks
A1: Set | B1: Variant A | C1: Variant B | D1: Variant C | E1: Your pick | F1: Cards to swap in/out or redo (optional)
A2: Love in the City | B2: First Date: classic date props and the city spots where it happens | C2: Meet-Cute: chance encounters around town | D2: Happily Ever After: the wedding finale | E2: B | F2: 3 and below
A3: Picture-Perfect Suburbia | B3: Home Sweet Home: the dream house and its gadgets | C3: Saturday in the Suburbs: diner, drive-in and teen fun | D3: Household Hijinks: chores and gadgets behind the sitcom gags | E3: A | F3: 3 and below, set A is overall more consistent even though cards in set B might be better individually
A4: Once Upon a Garden | B4: Enchanted Garden: magic plants and fairy homes | C4: Royal Tale: the castle, the crown and the royal treasures | D4: Wonderland Tea Party: the topsy-turvy garden party | E4: A | F4: 3 and below
A5: The Lost Island | B5: Shipwrecked: arriving on the island and settling in | C5: Jungle Expedition: into the heart of the island | D5: Treasure Hunt: digging up the reward | E5: C | F5: 3 and below

Sheet Summary
A1: Set | B1: Variant | C1: Cards | D1: Rated | E1: Average rating | F1: Rated 4-5 | G1: Share 4-5 of rated
A2: Love in the City | B2: A | C2: =COUNTIFS(Ratings!$B$2:$B$121,$A2,Ratings!$C$2:$C$121,$B2) -> 10 | D2: =COUNTIFS(Ratings!$B$2:$B$121,$A2,Ratings!$C$2:$C$121,$B2,Ratings!$I$2:$I$121,">=1") -> 10 | E2: =IFERROR(AVERAGEIFS(Ratings!$I$2:$I$121,Ratings!$B$2:$B$121,$A2,Ratings!$C$2:$C$121,$B2),"") -> 4.4 | F2: =COUNTIFS(Ratings!$B$2:$B$121,$A2,Ratings!$C$2:$C$121,$B2,Ratings!$I$2:$I$121,">=4") -> 8 | G2: =IFERROR(F2/D2,"") -> 0.8
A3: Love in the City | B3: B | C3: =COUNTIFS(Ratings!$B$2:$B$121,$A3,Ratings!$C$2:$C$121,$B3) -> 10 | D3: =COUNTIFS(Ratings!$B$2:$B$121,$A3,Ratings!$C$2:$C$121,$B3,Ratings!$I$2:$I$121,">=1") -> 10 | E3: =IFERROR(AVERAGEIFS(Ratings!$I$2:$I$121,Ratings!$B$2:$B$121,$A3,Ratings!$C$2:$C$121,$B3),"") -> 4.3 | F3: =COUNTIFS(Ratings!$B$2:$B$121,$A3,Ratings!$C$2:$C$121,$B3,Ratings!$I$2:$I$121,">=4") -> 9 | G3: =IFERROR(F3/D3,"") -> 0.9
A4: Love in the City | B4: C | C4: =COUNTIFS(Ratings!$B$2:$B$121,$A4,Ratings!$C$2:$C$121,$B4) -> 10 | D4: =COUNTIFS(Ratings!$B$2:$B$121,$A4,Ratings!$C$2:$C$121,$B4,Ratings!$I$2:$I$121,">=1") -> 10 | E4: =IFERROR(AVERAGEIFS(Ratings!$I$2:$I$121,Ratings!$B$2:$B$121,$A4,Ratings!$C$2:$C$121,$B4),"") -> 3.8 | F4: =COUNTIFS(Ratings!$B$2:$B$121,$A4,Ratings!$C$2:$C$121,$B4,Ratings!$I$2:$I$121,">=4") -> 7 | G4: =IFERROR(F4/D4,"") -> 0.7
A5: Love in the City | B5: all | C5: =COUNTIFS(Ratings!$B$2:$B$121,$A5) -> 30 | D5: =COUNTIFS(Ratings!$B$2:$B$121,$A5,Ratings!$I$2:$I$121,">=1") -> 30 | E5: =IFERROR(AVERAGEIFS(Ratings!$I$2:$I$121,Ratings!$B$2:$B$121,$A5),"") -> 4.1666667 | F5: =COUNTIFS(Ratings!$B$2:$B$121,$A5,Ratings!$I$2:$I$121,">=4") -> 24 | G5: =IFERROR(F5/D5,"") -> 0.8
A6: Picture-Perfect Suburbia | B6: A | C6: =COUNTIFS(Ratings!$B$2:$B$121,$A6,Ratings!$C$2:$C$121,$B6) -> 10 | D6: =COUNTIFS(Ratings!$B$2:$B$121,$A6,Ratings!$C$2:$C$121,$B6,Ratings!$I$2:$I$121,">=1") -> 10 | E6: =IFERROR(AVERAGEIFS(Ratings!$I$2:$I$121,Ratings!$B$2:$B$121,$A6,Ratings!$C$2:$C$121,$B6),"") -> 4.1 | F6: =COUNTIFS(Ratings!$B$2:$B$121,$A6,Ratings!$C$2:$C$121,$B6,Ratings!$I$2:$I$121,">=4") -> 7 | G6: =IFERROR(F6/D6,"") -> 0.7
A7: Picture-Perfect Suburbia | B7: B | C7: =COUNTIFS(Ratings!$B$2:$B$121,$A7,Ratings!$C$2:$C$121,$B7) -> 10 | D7: =COUNTIFS(Ratings!$B$2:$B$121,$A7,Ratings!$C$2:$C$121,$B7,Ratings!$I$2:$I$121,">=1") -> 10 | E7: =IFERROR(AVERAGEIFS(Ratings!$I$2:$I$121,Ratings!$B$2:$B$121,$A7,Ratings!$C$2:$C$121,$B7),"") -> 4.2 | F7: =COUNTIFS(Ratings!$B$2:$B$121,$A7,Ratings!$C$2:$C$121,$B7,Ratings!$I$2:$I$121,">=4") -> 9 | G7: =IFERROR(F7/D7,"") -> 0.9
A8: Picture-Perfect Suburbia | B8: C | C8: =COUNTIFS(Ratings!$B$2:$B$121,$A8,Ratings!$C$2:$C$121,$B8) -> 10 | D8: =COUNTIFS(Ratings!$B$2:$B$121,$A8,Ratings!$C$2:$C$121,$B8,Ratings!$I$2:$I$121,">=1") -> 10 | E8: =IFERROR(AVERAGEIFS(Ratings!$I$2:$I$121,Ratings!$B$2:$B$121,$A8,Ratings!$C$2:$C$121,$B8),"") -> 3.1 | F8: =COUNTIFS(Ratings!$B$2:$B$121,$A8,Ratings!$C$2:$C$121,$B8,Ratings!$I$2:$I$121,">=4") -> 3 | G8: =IFERROR(F8/D8,"") -> 0.3
A9: Picture-Perfect Suburbia | B9: all | C9: =COUNTIFS(Ratings!$B$2:$B$121,$A9) -> 30 | D9: =COUNTIFS(Ratings!$B$2:$B$121,$A9,Ratings!$I$2:$I$121,">=1") -> 30 | E9: =IFERROR(AVERAGEIFS(Ratings!$I$2:$I$121,Ratings!$B$2:$B$121,$A9),"") -> 3.8 | F9: =COUNTIFS(Ratings!$B$2:$B$121,$A9,Ratings!$I$2:$I$121,">=4") -> 19 | G9: =IFERROR(F9/D9,"") -> 0.63333333
A10: Once Upon a Garden | B10: A | C10: =COUNTIFS(Ratings!$B$2:$B$121,$A10,Ratings!$C$2:$C$121,$B10) -> 10 | D10: =COUNTIFS(Ratings!$B$2:$B$121,$A10,Ratings!$C$2:$C$121,$B10,Ratings!$I$2:$I$121,">=1") -> 10 | E10: =IFERROR(AVERAGEIFS(Ratings!$I$2:$I$121,Ratings!$B$2:$B$121,$A10,Ratings!$C$2:$C$121,$B10),"") -> 4.4 | F10: =COUNTIFS(Ratings!$B$2:$B$121,$A10,Ratings!$C$2:$C$121,$B10,Ratings!$I$2:$I$121,">=4") -> 10 | G10: =IFERROR(F10/D10,"") -> 1
A11: Once Upon a Garden | B11: B | C11: =COUNTIFS(Ratings!$B$2:$B$121,$A11,Ratings!$C$2:$C$121,$B11) -> 10 | D11: =COUNTIFS(Ratings!$B$2:$B$121,$A11,Ratings!$C$2:$C$121,$B11,Ratings!$I$2:$I$121,">=1") -> 10 | E11: =IFERROR(AVERAGEIFS(Ratings!$I$2:$I$121,Ratings!$B$2:$B$121,$A11,Ratings!$C$2:$C$121,$B11),"") -> 4 | F11: =COUNTIFS(Ratings!$B$2:$B$121,$A11,Ratings!$C$2:$C$121,$B11,Ratings!$I$2:$I$121,">=4") -> 6 | G11: =IFERROR(F11/D11,"") -> 0.6
A12: Once Upon a Garden | B12: C | C12: =COUNTIFS(Ratings!$B$2:$B$121,$A12,Ratings!$C$2:$C$121,$B12) -> 10 | D12: =COUNTIFS(Ratings!$B$2:$B$121,$A12,Ratings!$C$2:$C$121,$B12,Ratings!$I$2:$I$121,">=1") -> 10 | E12: =IFERROR(AVERAGEIFS(Ratings!$I$2:$I$121,Ratings!$B$2:$B$121,$A12,Ratings!$C$2:$C$121,$B12),"") -> 4.1 | F12: =COUNTIFS(Ratings!$B$2:$B$121,$A12,Ratings!$C$2:$C$121,$B12,Ratings!$I$2:$I$121,">=4") -> 7 | G12: =IFERROR(F12/D12,"") -> 0.7
A13: Once Upon a Garden | B13: all | C13: =COUNTIFS(Ratings!$B$2:$B$121,$A13) -> 30 | D13: =COUNTIFS(Ratings!$B$2:$B$121,$A13,Ratings!$I$2:$I$121,">=1") -> 30 | E13: =IFERROR(AVERAGEIFS(Ratings!$I$2:$I$121,Ratings!$B$2:$B$121,$A13),"") -> 4.1666667 | F13: =COUNTIFS(Ratings!$B$2:$B$121,$A13,Ratings!$I$2:$I$121,">=4") -> 23 | G13: =IFERROR(F13/D13,"") -> 0.76666667
A14: The Lost Island | B14: A | C14: =COUNTIFS(Ratings!$B$2:$B$121,$A14,Ratings!$C$2:$C$121,$B14) -> 10 | D14: =COUNTIFS(Ratings!$B$2:$B$121,$A14,Ratings!$C$2:$C$121,$B14,Ratings!$I$2:$I$121,">=1") -> 10 | E14: =IFERROR(AVERAGEIFS(Ratings!$I$2:$I$121,Ratings!$B$2:$B$121,$A14,Ratings!$C$2:$C$121,$B14),"") -> 3.8 | F14: =COUNTIFS(Ratings!$B$2:$B$121,$A14,Ratings!$C$2:$C$121,$B14,Ratings!$I$2:$I$121,">=4") -> 6 | G14: =IFERROR(F14/D14,"") -> 0.6
A15: The Lost Island | B15: B | C15: =COUNTIFS(Ratings!$B$2:$B$121,$A15,Ratings!$C$2:$C$121,$B15) -> 10 | D15: =COUNTIFS(Ratings!$B$2:$B$121,$A15,Ratings!$C$2:$C$121,$B15,Ratings!$I$2:$I$121,">=1") -> 10 | E15: =IFERROR(AVERAGEIFS(Ratings!$I$2:$I$121,Ratings!$B$2:$B$121,$A15,Ratings!$C$2:$C$121,$B15),"") -> 3.7 | F15: =COUNTIFS(Ratings!$B$2:$B$121,$A15,Ratings!$C$2:$C$121,$B15,Ratings!$I$2:$I$121,">=4") -> 6 | G15: =IFERROR(F15/D15,"") -> 0.6
A16: The Lost Island | B16: C | C16: =COUNTIFS(Ratings!$B$2:$B$121,$A16,Ratings!$C$2:$C$121,$B16) -> 10 | D16: =COUNTIFS(Ratings!$B$2:$B$121,$A16,Ratings!$C$2:$C$121,$B16,Ratings!$I$2:$I$121,">=1") -> 10 | E16: =IFERROR(AVERAGEIFS(Ratings!$I$2:$I$121,Ratings!$B$2:$B$121,$A16,Ratings!$C$2:$C$121,$B16),"") -> 4 | F16: =COUNTIFS(Ratings!$B$2:$B$121,$A16,Ratings!$C$2:$C$121,$B16,Ratings!$I$2:$I$121,">=4") -> 8 | G16: =IFERROR(F16/D16,"") -> 0.8
A17: The Lost Island | B17: all | C17: =COUNTIFS(Ratings!$B$2:$B$121,$A17) -> 30 | D17: =COUNTIFS(Ratings!$B$2:$B$121,$A17,Ratings!$I$2:$I$121,">=1") -> 30 | E17: =IFERROR(AVERAGEIFS(Ratings!$I$2:$I$121,Ratings!$B$2:$B$121,$A17),"") -> 3.8333333 | F17: =COUNTIFS(Ratings!$B$2:$B$121,$A17,Ratings!$I$2:$I$121,">=4") -> 20 | G17: =IFERROR(F17/D17,"") -> 0.66666667
A18: All sets | B18: all | C18: =COUNTA(Ratings!$A$2:$A$121) -> 120 | D18: =COUNTIFS(Ratings!$I$2:$I$121,">=1") -> 120 | E18: =IFERROR(AVERAGE(Ratings!$I$2:$I$121),"") -> 3.9916667 | F18: =COUNTIFS(Ratings!$I$2:$I$121,">=4") -> 86 | G18: =IFERROR(F18/D18,"") -> 0.71666667
A20: Formulas count and average the Ratings sheet (column I). Empty until ratings are entered.

Sheet References
A1: ID | B1: Name | C1: Category | D1: Image
A2: R1 | B2: Bottle | C2: 1
A3: R2 | B3: Graduation Cap | C3: 1
A4: R3 | B4: Fan Fold | C4: 1
A5: R4 | B5: Tea Cup | C5: 2
A6: R5 | B6: Mojito | C6: 2
A7: R6 | B7: Beach Bag | C7: 2
A8: R7 | B8: Bumpers | C8: 3
A9: R8 | B9: Computer | C9: 3
A10: R9 | B10: Boxing Gloves | C10: 3
A11: R10 | B11: Lighthouse | C11: 4
A12: R11 | B12: Coaster | C12: 4
A13: R12 | B13: Ferris Wheel | C13: 4
